// Error handling -> try, catch, finally, throw


try{

    //code test
    alert('hi');
    alert(x)
    alert('bye')

}catch(error){

    //handle error
    alert('Inside catch block')
}